<?xml version="1.0"?>
<robot name="arm3dof">
    <link name="base_link">
        <visual>
            <geometry>
                <box size="0.4 0.4 0.1"/>
            </geometry>
            <material name="gray">
                <color rgba="0.5 0.5 0.5 1"/>
            </material>
        </visual>
        <collision>
            <geometry>
                <box size="0.4 0.4 0.1"/>
            </geometry>
        </collision>
        <inertial>
            <mass value="1.0"/>
            <inertia ixx="0.01" ixy="0.0" ixz="0.0" iyy="0.01" iyz="0.0" izz="0.01"/>
        </inertial>
    </link>
    <link name="link_1">
        <visual>
            <geometry>
                <cylinder length="0.5" radius="0.05"/>
            </geometry>
            <origin xyz="0 0 0.25" rpy="0 0 0"/>
            <material name="blue">
                <color rgba="0.0 0.0 1.0 1"/>
            </material>
        </visual>
        <collision>
            <geometry>
                <cylinder length="0.5" radius="0.05"/>
            </geometry>
            <origin xyz="0 0 0.25" rpy="0 0 0"/>
        </collision>
        <inertial>
            <mass value="0.5"/>
            <inertia ixx="0.005" ixy="0.0" ixz="0.0" iyy="0.005" iyz="0.0" izz="0.005"/>
        </inertial>
    </link>
    <link name="link_2">
        <visual>
            <geometry>
                <cylinder length="0.5" radius="0.05"/>
            </geometry>
            <origin xyz="0 0 0.25" rpy="0 0 0"/>
            <material name="green">
                <color rgba="0.0 1.0 0.0 1"/>
            </material>
        </visual>
        <collision>
            <geometry>
                <cylinder length="0.5" radius="0.05"/>
            </geometry>
            <origin xyz="0 0 0.25" rpy="0 0 0"/>
        </collision>
        <inertial>
            <mass value="0.4"/>
            <inertia ixx="0.004" ixy="0.0" ixz="0.0" iyy="0.004" iyz="0.0" izz="0.004"/>
        </inertial>
    </link>
    <link name="link_3">
        <visual>
            <geometry>
                <cylinder length="0.5" radius="0.05"/>
            </geometry>
            <origin xyz="0 0 0.25" rpy="0 0 0"/>
            <material name="red">
                <color rgba="1.0 0.0 0.0 1"/>
            </material>
        </visual>
        <collision>
            <geometry>
                <cylinder length="0.5" radius="0.05"/>
            </geometry>
            <origin xyz="0 0 0.25" rpy="0 0 0"/>
        </collision>
        <inertial>
            <mass value="0.3"/>
            <inertia ixx="0.003" ixy="0.0" ixz="0.0" iyy="0.003" iyz="0.0" izz="0.003"/>
        </inertial>
    </link>
    <joint name="j1_base_jaw" type="revolute">
        <parent link="base_link"/>
        <child link="link_1"/>
        <origin xyz="0 0 0.05" rpy="0 0 0"/>
        <axis xyz="0 0 1"/>
        <limit lower="-3.14" upper="3.14" effort="10" velocity="1.0"/>
    </joint>
    <joint name="j2_shoulder" type="revolute">
        <parent link="link_1"/>
        <child link="link_2"/>
        <origin xyz="0 0 0.5" rpy="0 0 0"/>
        <axis xyz="0 1 0"/>
        <limit lower="-1.57" upper="1.57" effort="10" velocity="1.0"/>
    </joint>
    <joint name="j3_elbow" type="revolute">
        <parent link="link_2"/>
        <child link="link_3"/>
        <origin xyz="0 0 0.5" rpy="0 0 0"/>
        <axis xyz="0 1 0"/>
        <limit lower="-1.57" upper="1.57" effort="10" velocity="1.0"/>
    </joint>
    <gazebo>
        <plugin name="gz::sim::systems::JointPositionController"
                filename="libgz-sim-joint-position-controller-system.so">
            <joint_name>j1_base_jaw</joint_name>
            <topic>j1_position_cmd</topic>
            <p_gain>10.0</p_gain>
            <i_gain>0.0</i_gain>
            <d_gain>0.1</d_gain>
        </plugin>
    </gazebo>
    <gazebo>
        <plugin name="gz::sim::systems::JointPositionController"
                filename="libgz-sim-joint-position-controller-system.so">
            <joint_name>j2_shoulder</joint_name>
            <topic>j2_position_cmd</topic>
            <p_gain>10.0</p_gain>
            <i_gain>0.0</i_gain>
            <d_gain>0.1</d_gain>
        </plugin>
    </gazebo>
    <gazebo>
        <plugin name="gz::sim::systems::JointPositionController"
                filename="libgz-sim-joint-position-controller-system.so">
            <joint_name>j3_elbow</joint_name>
            <topic>j3_position_cmd</topic>
            <p_gain>10.0</p_gain>
            <i_gain>0.0</i_gain>
            <d_gain>0.1</d_gain>
        </plugin>
    </gazebo>
    <gazebo>
        <plugin filename="libgz-sim-joint-state-publisher-system.so"
                name="gz::sim::systems::JointStatePublisher">
            <topic>joint_states</topic>
        </plugin>
    </gazebo>
</robot>